## Introduction to Exception Handling
Exception handling is a technique used in programming to handle errors and unexpected situations that may arise during the execution of a program. It allows the program to continue running, even if an error occurs. In C++, exception handling is done using try-catch blocks.

### Overview of Exception Handling
The basic idea behind exception handling is that when an error occurs, the program throws an exception, which can then be caught and handled by the program. This helps to improve the robustness and fault tolerance of the program.

### Importance of Exception Handling
Exception handling is important for several reasons, including:

* Robustness and Fault Tolerance: Exception handling allows the program to continue running even if an error occurs. This ability to recover from errors and continue execution makes the program more robust and fault-tolerant.
* Separation of concerns: Exception handling allows the program to separate error handling from normal program logic, which makes the code more modular and easier to maintain.

## Basics of Exception Handling
Exception handling in C++ involves the use of a `try-catch` block. The `try` block contains the code that may throw an exception, while the `catch` block contains the code that handles the exception.

Here's an example that demonstrates the use of `try-catch` blocks in C++:
```cpp
#include <iostream>

using namespace std;

int main() {
   int x = 10, y = 0, z;

   try {
      if (y == 0) {
         throw "Division by zero!"; // Throws an exception
      }
      z = x / y;
      cout << "z = " << z << endl;
   }
   catch (const char* error) {
      cerr << "Error: " << error << endl; // Catches the exception and handle it
   }

   return 0;
}
```
In this example, we are dividing `x` by `y`, where `y` is zero. This will result in a division by zero error. We are handling this error using a `try-catch` block. If `y` is zero, we are throwing an exception with the message "Division by zero!". In the `catch` block, we are printing the error message to the standard error stream.

### Throwing Exceptions Using the `throw` Keyword
When an error occurs in your C++ program, you can use the `throw` keyword to throw an exception. When an exception is thrown, the program will stop executing the current function and start looking for a `catch` block that can handle the exception.

Here's an example that demonstrates how to `throw` an exception using the throw keyword:
```cpp
#include <iostream>
#include <stdexcept>

using namespace std;

double divide(double x, double y) {
   if (y == 0) {
      throw runtime_error("Divide by zero error!"); // Throws a runtime_error exception with the message "Divide by zero error!"
   }
   return x / y;
}

int main() {
   double x = 10.0, y = 0.0;

   try {
      double result = divide(x, y);
      cout << "Result = " << result << endl;
   }
   catch (const runtime_error& e) {
      cerr << "Error: " << e.what() << endl; // Catches the runtime_error exception and handle it
   }

   return 0;
}
```
In this example, we have a function called `divide` that takes two double arguments `x` and `y` and returns their quotient. If `y` is equal to zero, we throw a `std::runtime_error` exception with the message "Divide by zero error!".

In the main function, we call the `divide` function with arguments `x` and `y`. If the `divide` function throws a `std::runtime_error` exception, we catch the exception and handl it appropriately. In this case, we print the error message "Error: Divide by zero error!" to the standard error stream.

The `#include <stdexcept>` directive in the beginning of the above code is a preprocessor directive in C++ that includes the `<stdexcept>` header file from the C++ Standard Library. This header file provides a set of standard exception classes that can be used for handling various types of runtime errors.

The `<stdexcept>` header file defines several exception classes, including `std::exception`, which is the base class for all standard exceptions. Other commonly used exception classes provided by `<stdexcept>` include `std::runtime_error`, `std::logic_error`, and `std::out_of_range`, among others.

### Comparison of Error Handling Techniques (return codes vs. exceptions)
Traditionally, error handling in C++ has been done using return codes. However, this can be cumbersome and error-prone, especially in large programs. Exceptions provide a more elegant and powerful way to handle errors. When an error occurs, the program can throw an exception, which can then be caught and handled by the program. This allows the program to separate error handling from normal program logic, which makes the code more modular and easier to maintain.

Exceptions also provide more information about the error that occurred. An exception can include a message or other data that provides more details about the error, which can help with debugging.

Here's an example that demonstrates the difference between return codes and exceptions:
```cpp
#include <iostream>
using namespace std;

// Example using return codes
int divide(int x, int y, int& result) {
   if (y == 0) {
      return -1; // Error: Division by zero
   }
   result = x / y;
   return 0; // Success
}

int main() {
   int x = 10, y = 0, z;

   if (divide(x, y, z) == -1) {
      cerr << "Error: Division by zero!" << endl;
   }
   else {
      cout << "z = " << z << endl;
   }

   return 0;
}
```
```cpp
#include <iostream>
using namespace std;

// Example using exceptions
int divide(int x, int y) {
   if (y == 0) {
      throw std::runtime_error("Division by zero!"); // Throws exception
   }
   return x / y;
}

int main() {
   int x = 10, y = 0, z;

   try {
      z = divide(x, y);
      cout << "z = " << z << endl;
   }
   catch (const std::exception& e) {
      cerr << "Error: " << e.what() << endl;
   }

   return 0;
}
```
In the first example, the `divide` function returns an error code to indicate that an error occurred. In the `main` function, we check the return code to determine if an error occurred.

In the second example, the `divide` function throws an exception when an error occurs. In the `main` function, we catch the exception and handle it. The exception provides more information about the error that occurred.

In large programs, the use of exceptions can lead to more maintainable and readable code, as error handling logic is separated from the main control flow, reducing clutter and allowing for more focused code organization. Exceptions also offer better error propagation and centralization of error handling, making it easier to handle errors consistently and cleanly throughout the program.

## Standard Exception Classes
C++ provides a number of standard exception classes that you can use to handle errors. These classes are defined in the `<stdexcept>` header file. Some common exception classes are `logic_error`, `runtime_error`, `out_of_range`, `invalid_argument`, and `domain_error`.

Some of the common standard exception classes in C++ include:
* `std::logic_error`: This exception is thrown when a logical error occurs. Examples of logical errors include trying to open a file that doesn't exist, or dividing a number by zero.

* `std::runtime_error`: This exception is thrown when a runtime error occurs. Examples of runtime errors include running out of memory, or encountering an unexpected end-of-file while reading data. 

* `std::out_of_range`: This exception is thrown when an attempt is made to access an element outside the bounds of a container, such as a vector or an array.

* `std::invalid_argument`: This exception is thrown when an invalid argument is passed to a function. For example, passing a negative value to a function that expects a positive value would result in an `std::invalid_argument` exception.

* `std::domain_error`: This exception is thrown when a function is called with an argument that is outside of its domain. For example, taking the square root of a negative number would result in a `std::domain_error`.

* `std::length_error`: This exception is thrown when a function or operation is attempted on a container that exceeds its maximum size.

Using these standard exception classes can help make your code more robust and easier to maintain. When an exception is thrown, it's important to catch it and handle it appropriately to prevent program crashes or undefined behavior.

Here's an example that demonstrates the use of the `std::out_of_range` and `std::invalid_argument` exception classes:
```cpp
#include <iostream>
#include <stdexcept>

using namespace std;

int main() {
    int arr[] = {1, 2, 3, 4, 5};
    int size = sizeof(arr) / sizeof(arr[0]);
    int index;

    try {
        cout << "Enter an index to access the element: ";
        cin >> index;

        if (index < 0 || index >= size) {
            throw out_of_range("Index out of range!"); // throws std::out_of_range exception if the index is out of range
        }

        cout << "Element at index " << index << " is " << arr[index] << endl;
    } catch (const out_of_range &e) {
        cerr << "Error: " << e.what() << endl; // Catches the std::out_of_range exception and handles it
    } catch (const invalid_argument &e) {
        cerr << "Error: " << e.what() << endl; // Catches the std::invalid_argument exception and handles it
    }

    return 0;
}
```
The above code demonstrates error handling using exceptions for accessing elements in an array. Instead of using a vector, an integer array `arr` is defined with the elements `{1, 2, 3, 4, 5}`. 

The program prompts the user to enter an index to access an element in the array. It then checks if the index is within the valid range. If the index is out of range, an `out_of_range` exception is thrown with the message "Index out of range!".

The exceptions are caught using `catch` blocks. If an `out_of_range` exception is caught, the error message is printed to the standard error stream. 

This approach allows for more robust error handling, as it provides more detailed information about the error that occurred.

## Catching Multiple Exceptions and Exception Hierarchies
You can catch multiple exception types using multiple catch blocks. This allows you to handle different types of exceptions in different ways. In addition, you can catch exceptions by reference, value, or pointer. Catching by reference or pointer is usually more efficient, but you need to be careful to ensure that the object being pointed to is not destroyed before the catch block completes.
You can also catch exceptions by their base class. This allows you to catch multiple exception types with a single catch block. 

Exceptions are organized in a hierarchy, with more specific exceptions derived from more general exceptions. When catching exceptions, it is important to catch the most specific exception types first, and the more general types last.

Here's an example that demonstrates how to catch multiple exception types using multiple catch blocks, catch exceptions by reference and pointer, and catch exceptions by their base class:
```cpp
#include <iostream>
#include <stdexcept>

using namespace std;

int divide(int x, int y) {
   if (y == 0) {
      throw logic_error("Divide by zero error!"); // Throws a logic_error exception with the message "Divide by zero error!"
   }
   return x / y;
}

int main() {
   try {
      int x = 10, y = 0;
      double result = divide(x, y);
      cout << "Result = " << result << endl;
   }
   catch (const runtime_error& e) {
      cerr << "Runtime error: " << e.what() << endl; // Catches the runtime_error exception and handles it
   }
   catch (const exception& e) {
      cerr << "Exception: " << e.what() << endl; // Catches any other exception derived from std::exception
   }
   catch (...) {
      cerr << "Unknown exception occurred!" << endl; // Catches any other exception that is not derived from std::exception
   }

   return 0;
}
```
In the `divide` function, we check if the divisor `y` is zero. If it is, we throw a `logic_error` exception with the message "Divide by zero error!". This simulates a division by zero error. 

In the `main` function, we call the `divide` function with `x` as 10 and `y` as 0. Since the divisor is zero, an exception is thrown. 

The code uses multiple catch blocks to handle different types of exceptions. The first catch block catches a `runtime_error` exception and outputs an error message to the standard error stream (`cerr`). However, since the code throws a `logic_error` exception, this catch block will not be executed. 

The second catch block catches a `const exception&` exception, which is a base class for all standard exceptions. It outputs the error message to the standard error stream. Since `logic_error` is derived from `std::exception`, this catch block will handle the thrown exception. 

The last catch block catches any other exception that is not derived from `std::exception`. It outputs a generic error message indicating that an unknown exception occurred. 

By catching multiple exception types using multiple catch blocks, we are able to handle different types of exceptions in different ways. By catching exceptions by reference or pointer, we are able to handle exceptions more efficiently. By catching exceptions by their base class, we are able to catch multiple exception types with a single catch block. And by understanding the exception hierarchy and the order of catch blocks, we are able to catch the most specific exception types first, and the more general types last.