## Introduction to Exception Handling
Exception handling is a technique used in programming to handle errors and unexpected situations that may arise during the execution of a program. It allows the program to continue running, even if an error occurs. In C++, exception handling is done using try-catch blocks.

### Overview of Exception Handling
The basic idea behind exception handling is that when an error occurs, the program throws an exception, which can then be caught and handled by the program. This helps to improve the robustness and fault tolerance of the program.

### Importance of Exception Handling
Exception handling is important for several reasons, including:

* Robustness: Exception handling allows the program to continue running even if an error occurs, which makes the program more robust.
* Fault tolerance: By handling exceptions, the program can recover from errors and continue running, which makes it more fault-tolerant.
* Separation of concerns: Exception handling allows the program to separate error handling from normal program logic, which makes the code more modular and easier to maintain.

## Basics of Exception Handling
Exception handling in C++ involves the use of a `try-catch` block. The `try` block contains the code that may throw an exception, while the `catch` block contains the code that handles the exception.

The `try` block is used to enclose the code that may throw an exception. If an exception is thrown within the `try` block, the program jumps to the `catch` block.

Here's an example that demonstrates the use of try-catch blocks in C++:
```cpp
#include <iostream>

using namespace std;

int main() {
   int x = 10, y = 0, z;

   try {
      if (y == 0) {
         throw "Division by zero!"; // Throw an exception
      }
      z = x / y;
      cout << "z = " << z << endl;
   }
   catch (const char* error) {
      cerr << "Error: " << error << endl; // Catch the exception and handle it
   }

   return 0;
}
```
In this example, we are dividing `x` by `y`, where `y` is zero. This will result in a division by zero error. We are handling this error using a `try-catch` block. If `y` is zero, we are throwing an exception with the message "Division by zero!". In the `catch` block, we are printing the error message to the standard error stream.

### Throwing Exceptions Using the `throw` Keyword
When an error occurs in your C++ program, you can use the `throw` keyword to throw an exception. When an exception is thrown, the program will stop executing the current function and start looking for a `catch` block that can handle the exception.

Here's an example that demonstrates how to `throw` an exception using the throw keyword:
```cpp
#include <iostream>
#include <stdexcept>

using namespace std;

double divide(double x, double y) {
   if (y == 0) {
      throw runtime_error("Divide by zero error!"); // Throw a runtime_error exception with the message "Divide by zero error!"
   }
   return x / y;
}

int main() {
   double x = 10.0, y = 0.0;

   try {
      double result = divide(x, y);
      cout << "Result = " << result << endl;
   }
   catch (const runtime_error& e) {
      cerr << "Error: " << e.what() << endl; // Catch the runtime_error exception and handle it
   }

   return 0;
}
```
In this example, we have a function called `divide` that takes two double arguments `x` and `y` and returns their quotient. If `y` is equal to zero, we are throwing a `std::runtime_error` exception with the message "Divide by zero error!".

In the main function, we are calling the divide function with arguments `x` and `y`. If the divide function throws a `std::runtime_error` exception, we are catching the exception and handling it appropriately. In this case, we are printing the error message "Error: Divide by zero error!" to the standard error stream.

### Comparison of Error Handling Techniques (return codes vs. exceptions)
Traditionally, error handling in C++ has been done using return codes. However, this can be cumbersome and error-prone, especially in large programs. Exceptions provide a more elegant and powerful way to handle errors. When an error occurs, the program can throw an exception, which can then be caught and handled by the program. This allows the program to separate error handling from normal program logic, which makes the code more modular and easier to maintain.

Exceptions also provide more information about the error that occurred. An exception can include a message or other data that provides more details about the error, which can help with debugging.

Here's an example that demonstrates the difference between return codes and exceptions:
```cpp
// Example using return codes
int divide(int x, int y, int& result) {
   if (y == 0) {
      return -1; // Error: Division by zero
   }
   result = x / y;
   return 0; // Success
}

int main() {
   int x = 10, y = 0, z;

   if (divide(x, y, z) == -1) {
      cerr << "Error: Division by zero!" << endl;
   }
   else {
      cout << "z = " << z << endl;
   }

   return 0;
}
```
```cpp
// Example using exceptions
int divide(int x, int y) {
   if (y == 0) {
      throw std::runtime_error("Division by zero!"); // Throw exception
   }
   return x / y;
}

int main() {
   int x = 10, y = 0, z;

   try {
      z = divide(x, y);
      cout << "z = " << z << endl;
   }
   catch (const std::exception& e) {
      cerr << "Error: " << e.what() << endl;
   }

   return 0;
}
```
In the first example, the `divide` function returns an error code to indicate that an error occurred. In the `main` function, we check the return code to determine if an error occurred.

In the second example, the `divide` function throws an exception when an error occurs. In the `main` function, we catch the exception and handle it. The exception provides more information about the error that occurred.

## Standard Exception Classes
C++ provides a number of standard exception classes that you can use to handle errors. These classes are defined in the `<stdexcept>` header file. Some common exception classes are `logic_error`, `runtime_error`, `out_of_range`, `invalid_argument`, and `domain_error`.

The standard exception classes provided by C++ are a set of predefined classes that you can use to handle common types of errors that may occur in your program. These classes are defined in the `<stdexcept>` header file.

Some of the common standard exception classes in C++ include:
* `std::logic_error`: This exception is thrown when a logical error occurs. Examples of logical errors include trying to open a file that doesn't exist, or dividing a number by zero.

* `std::runtime_error`: This exception is thrown when a runtime error occurs. Examples of runtime errors include running out of memory, or encountering an unexpected end-of-file while reading data. 

* `std::out_of_range`: This exception is thrown when an attempt is made to access an element outside the bounds of a container, such as a vector or an array.

* `std::invalid_argument`: This exception is thrown when an invalid argument is passed to a function. For example, passing a negative value to a function that expects a positive value would result in an `std::invalid_argument` exception.

* `std::domain_error`: This exception is thrown when a function is called with an argument that is outside of its domain. For example, taking the square root of a negative number would result in a `std::domain_error`.

* `std::length_error`: This exception is thrown when a function or operation is attempted on a container that exceeds its maximum size.

Using these standard exception classes can help make your code more robust and easier to maintain. When an exception is thrown, it's important to catch it and handle it appropriately to prevent program crashes or undefined behavior.

Here's an example that demonstrates the use of the `std::out_of_range` and `std::invalid_argument` exception classes:
```cpp
#include <iostream>
#include <vector>
#include <stdexcept>

using namespace std;

int main() {
   vector<int> v = {1, 2, 3, 4, 5};
   int index;
   
   try {
      cout << "Enter an index to access the element: ";
      cin >> index;
      
      if (index < 0 || index >= v.size()) {
         throw out_of_range("Index out of range!"); // throw std::out_of_range exception if the index is out of range
      }
      
      cout << "Element at index " << index << " is " << v[index] << endl;
   }
   catch (const out_of_range& e) {
      cerr << "Error: " << e.what() << endl; // Catch the std::out_of_range exception and handle it
   }
   catch (const invalid_argument& e) {
      cerr << "Error: " << e.what() << endl; // Catch the std::invalid_argument exception and handle it
   }
   
   return 0;
}
```
In this example, we are creating a vector `v` containing five elements. We are then asking the user to enter an index to access an element from the vector. If the user enters an invalid index (either negative or greater than or equal to the size of the vector), we are throwing a `std::out_of_range` exception with the message "Index out of range!". If the user enters an invalid argument (for example, a non-integer value), we are throwing a `std::invalid_argument` exception.

In the `catch` block, we are catching the `std::out_of_range` and `std::invalid_argument` exceptions separately and handling them appropriately. In the next section, you will learn about catching multiple exceptions. If a `std::out_of_range` exception is caught, we are printing the error message "Error: Index out of range!" to the standard error stream. If a `std::invalid_argument` exception is caught, we are printing the error message "Error: Invalid argument!" to the standard error stream.

By catching and handling these exceptions, we are able to gracefully handle errors that may occur when accessing elements from a vector.

## Catching Multiple Exceptions and Exception Hierarchies
You can catch multiple exception types using multiple catch blocks. This allows you to handle different types of exceptions in different ways. In addition, you can catch exceptions by reference, value, or pointer. Catching by reference or pointer is usually more efficient, but you need to be careful to ensure that the object being pointed to is not destroyed before the catch block completes.
You can also catch exceptions by their base class. This allows you to catch multiple exception types with a single catch block. 

Exceptions are organized in a hierarchy, with more specific exceptions derived from more general exceptions. When catching exceptions, it is important to catch the most specific exception types first, and the more general types last.

Here's an example that demonstrates how to catch multiple exception types using multiple catch blocks, catch exceptions by reference and pointer, and catch exceptions by their base class:
```cpp
#include <iostream>
#include <stdexcept>

using namespace std;

int divide(int x, int y) {
   if (y == 0) {
      throw runtime_error("Divide by zero error!"); // Throw a runtime_error exception with the message "Divide by zero error!"
   }
   return x / y;
}

int main() {
   try {
      int x = 10, y = 0;
      double result = divide(x, y);
      cout << "Result = " << result << endl;
   }
   catch (const runtime_error& e) {
      cerr << "Error: " << e.what() << endl; // Catch the runtime_error exception and handle it
   }
   catch (const exception& e) {
      cerr << "Error: " << e.what() << endl; // Catch any other exception derived from std::exception
   }
   catch (...) {
      cerr << "Unknown exception occurred!" << endl; // Catch any other exception that is not derived from std::exception
   }

   return 0;
}
```
In this example, we are defining a function called `divide` that takes two integer arguments `x` and `y` and returns their quotient. If `y` is equal to zero, we are throwing a `std::runtime_error` exception with the message "Divide by zero error!".

In the `main` function, we are calling the `divide` function with arguments `x` and `y`. We are catching the `std::runtime_error` exception using a `catch` block that catches exceptions of type `std::runtime_error` by reference. We are also catching any other exception derived from std::exception using a catch block that catches exceptions of type `std::exception` by reference. Finally, we are catching any other exception that is not derived from `std::exception` using a catch block that catches any exception type.

By catching multiple exception types using multiple catch blocks, we are able to handle different types of exceptions in different ways. By catching exceptions by reference or pointer, we are able to handle exceptions more efficiently. By catching exceptions by their base class, we are able to catch multiple exception types with a single catch block. And by understanding the exception hierarchy and the order of catch blocks, we are able to catch the most specific exception types first, and the more general types last.