## Creating Custom Exception
In C++, you can create your own custom exception classes by inheriting from `std::exception` or other standard exception classes. This allows you to define your own exception types that are tailored to your program's needs.

Here's an example that demonstrates how to create a custom exception class by inheriting from `std::exception`:
```cpp
#include <iostream>
#include <stdexcept>

using namespace std;

class MyException : public std::exception {
public:
   const char* what() const noexcept override {
      return "My custom exception occurred!";
   }
};

int main() {
   try {
      throw MyException(); // Throw a custom exception of type MyException
   }
   catch (const MyException& e) {
      cerr << "Error: " << e.what() << endl; // Catch the custom exception and handle it
   }
   catch (const std::exception& e) {
      cerr << "Error: " << e.what() << endl; // Catch any other exception and handle it
   }

   return 0;
}
```
In this example, we are defining a custom exception class called `MyException`, which inherits from `std::exception`. The `MyException` class overrides the `what` function to return a custom error message. By overriding this function in MyException, we are able to provide a custom error message that is specific to our program. In the example, the `what()` function is overridden to return the message "My custom exception occurred!".

In the `main` function, we are throwing a custom exception of type `MyException`. In the `catch` block, we are catching the `MyException` exception and handling it by printing the error message to the standard error stream. We are also catching any other exception that may occur and handling it in the same way.

By creating custom exception classes, we can define our own exception types that are tailored to our program's needs. This allows us to provide more informative error messages and handle errors in a more specific way.

## Rethrowing Exceptions and Exception Propagation
You can rethrow an exception that has been caught using the `throw` keyword without an operand. This allows you to propagate the exception to an outer scope or rethrow it after handling it in a catch block. When an exception is thrown from a function, it can be propagated up the call stack to a higher-level function that can handle it. This allows you to handle exceptions at an appropriate level of abstraction in your program. 

When catching an exception in a nested try-catch block, you can rethrow the exception to an outer catch block by using the `throw` keyword without an operand.

Here's an example that demonstrates how to rethrow an exception using the `throw` keyword without an operand, propagate exceptions through function calls, and catch and rethrow exceptions in nested try-catch blocks:
```cpp
#include <iostream>
#include <stdexcept>

using namespace std;

void function3() {
   cout << "In function3" << endl;
   throw runtime_error("Exception in function3!"); // Throw a runtime_error exception with the message "Exception in function3!"
}

void function2() {
   cout << "In function2" << endl;
   try {
      function3();
   }
   catch (...) {
      cerr << "Exception caught in function2, rethrowing..." << endl;
      throw; // Rethrow the exception to the calling function
   }
}

void function1() {
   cout << "In function1" << endl;
   try {
      function2();
   }
   catch (const runtime_error& e) {
      cerr << "Exception caught in function1: " << e.what() << endl;
   }
}

int main() {
   try {
      function1();
   }
   catch (const runtime_error& e) {
      cerr << "Exception caught in main: " << e.what() << endl;
   }

   return 0;
}
```
In this example, we are defining three functions called `function1`, `function2`, and `function3`. The `function3` function throws a `std::runtime_error` exception with the message "Exception in function3!". The `function2` function calls `function3` in a try block and catches any exception that occurs. If an exception occurs, it rethrows the exception to the calling function using the `throw` keyword without an operand. The `function1` function calls `function2` in a try block and catches any `std::runtime_error` exceptions that occur. The `main` function calls `function1` in a try block and catches any `std::runtime_error` exceptions that occur.

By rethrowing an exception using the `throw` keyword without an operand, we are able to propagate the exception to an outer scope or rethrow it after handling it in a catch block. By propagating exceptions through function calls, we are able to handle exceptions at an appropriate level of abstraction in our program. And by catching and rethrowing exceptions in nested try-catch blocks, we are able to handle exceptions that occur at different levels of abstraction in our program.

## The `noexcept` Specifier (C++11 onwards)
The `noexcept` specifier is used to indicate that a function does not throw any exceptions. This allows the compiler to optimize the code for performance and generate more efficient code. You can use the `noexcept` specifier to indicate that a function does not throw any exceptions. This can be useful for functions that need to be highly optimized for performance.

When overloading a function, it is important to use the `noexcept` specifier consistently across all overloaded functions to avoid unexpected behavior at runtime.

The move constructor and move assignment operator are typically marked as noexcept to indicate that they do not throw exceptions. This allows objects to be moved more efficiently.

Here's an example that demonstrates how to use the `noexcept` specifier to indicate that a function does not throw exceptions and how to overload a function using the `noexcept` specifier:
```cpp
#include <iostream>
#include <stdexcept>

using namespace std;

void function1() noexcept {
   cout << "In function1" << endl;
}

void function2() {
   cout << "In function2" << endl;
   throw runtime_error("Exception in function2!"); // Throw a runtime_error exception with the message "Exception in function2!"
}

void function3() noexcept(false) {
   cout << "In function3" << endl;
   throw runtime_error("Exception in function3!"); // Throw a runtime_error exception with the message "Exception in function3!"
}

void foo() noexcept;
void foo() noexcept(true) { // This is fine
   cout << "In foo" << endl;
}

void bar() noexcept(false);
void bar() noexcept(false) { // This is also fine
   cout << "In bar" << endl;
}

int main() {
   function1(); // Call function1, which does not throw exceptions
   try {
      function2(); // Call function2, which throws a runtime_error exception
   }
   catch (const runtime_error& e) {
      cerr << "Exception caught in main: " << e.what() << endl;
   }
   try {
      function3(); // Call function3, which throws a runtime_error exception
   }
   catch (const runtime_error& e) {
      cerr << "Exception caught in main: " << e.what() << endl;
   }
   foo(); // Call foo, which is marked as noexcept(true)
   bar(); // Call bar, which is marked as noexcept(false)

   return 0;
}
```
In this example, we are defining three functions called `function1`, `function2`, and `function3`. The `function1` function is marked as `noexcept` and does not throw any exceptions. The `function2` function throws a `std::runtime_error` exception with the message "Exception in function2!". The `function3` function is marked as `noexcept(false)` and throws a `std::runtime_error` exception with the message "Exception in function3!".

We are also defining two overloaded functions called `foo` and `bar`. The `foo` function is marked as `noexcept` with a value of `true`, indicating that it does not throw any exceptions. The `bar` function is marked as `noexcept` with a value of `false`, indicating that it may throw exceptions.

In the `main` function, we are calling `function1`, `function2`, and `function3`. Since `function1` and `function2` have different noexcept specifications, the compiler can generate more efficient code for `function1`. When calling `function2` and `function3`, we are using try-catch blocks to catch any `std::runtime_error` exceptions that are thrown.

We are also calling the `foo` and `bar` functions, which have different noexcept specifications. `foo` is marked as `noexcept(true)`, indicating that it does not throw any exceptions, while `bar` is marked as `noexcept(false)`, indicating that it may throw exceptions.

By using the `noexcept` specifier, we can indicate to the compiler which functions do not throw exceptions, allowing the compiler to generate more efficient code. We can also use the `noexcept` specifier consistently across overloaded functions to avoid unexpected behavior at runtime. Finally, we can mark the move constructor and move assignment operator as `noexcept` to allow objects to be moved more efficiently.

## The `std::terminate` and `std::unexpected` Functions
`std::terminate` is a function that is called when the exception handling mechanism has been unable to find a suitable catch block for an exception. `std::unexpected` is a function that is called when an exception is thrown from a function that is not declared to throw any exceptions. These functions allow you to customize the behavior of your program when exceptional conditions occur.

You can customize the behavior of `std::terminate` and `std::unexpected` by providing your own implementations of these functions. This allows you to take control of how your program behaves when exceptional conditions occur.

Here's an example that demonstrates how to customize the behavior of `std::terminate`:
```cpp
#include <iostream>
#include <exception>

using namespace std;

void my_terminate() {
   cerr << "Unhandled exception!" << endl;
   exit(1);
}

int main() {
   set_terminate(my_terminate); // Set the terminate handler to my_terminate

   try {
      throw runtime_error("Exception!"); // Throw a runtime_error exception with the message "Exception!"
   }
   catch (...) {
      cerr << "Exception caught!" << endl;
   }

   return 0;
}
```
In this example, we are defining a function called `my_terminate`, which is called by `std::terminate` when an unhandled exception occurs. The `my_terminate` function prints an error message to `cerr` and exits the program with an error code of 1.

We are then setting the terminate handler to `my_terminate` using the `set_terminate` function.

We are then throwing a `std::runtime_error` exception with the message "Exception!". Since there is no catch block for this exception, `std::terminate` is called, which in turn calls `my_terminate`.

By providing our own implementation of `my_terminate`, we can customize the behavior of our program when unhandled exceptions occur.

Here's an example that demonstrates how to customize the behavior of `std::unexpected`:
```cpp
#include <iostream>
#include <exception>

using namespace std;

class my_exception : public exception {
public:
   const char* what() const noexcept override {
      return "My exception!";
   }
};

void my_unexpected() {
   cerr << "Unexpected exception!" << endl;
   exit(1);
}

void my_function() throw(my_exception) {
   throw my_exception(); // Throw a my_exception exception
}

int main() {
   set_unexpected(my_unexpected); // Set the unexpected handler to my_unexpected

   try {
      my_function(); // Call my_function, which throws a my_exception exception
   }
   catch (const my_exception& e) {
      cerr << "Caught my_exception: " << e.what() << endl;
   }

   return 0;
}
```
In this example, we are defining a custom exception class called `my_exception`, which inherits from `std::exception` and overrides the `what` function to return a custom error message.

We are then defining a function called `my_unexpected`, which is called by `std::unexpected` when an unexpected exception is thrown. The `my_unexpected` function prints an error message to `cerr` and exits the program with an error code of 1.

We are then defining a function called `my_function`, which is declared to throw `my_exception`. We are then calling `my_function`, which throws a `my_exception` exception. Since `my_function` is not declared to throw any other exceptions, if an exception other than my_exception is thrown, `std::unexpected` will be called.

We are then setting the unexpected handler to `my_unexpected` using the `set_unexpected` function.

Finally, we are catching the `my_exception` exception that is thrown by `my_function` and printing a message to `cerr`.

By providing our own implementation of `my_unexpected`, we can customize the behavior of our program when unexpected exceptions occur.

## Stack Unwinding and Resource Management
### Understanding Stack Unwinding During Exception Handling
When an exception is thrown, the C++ runtime system begins searching the call stack for a suitable catch block. This process is called stack unwinding. During stack unwinding, the runtime system calls the destructors of all local objects that were created since the try block was entered.

### Resource Management in the Context of Exception Handling (RAII)
Resource management is an important concern in exception handling. In C++, the RAII (Resource Acquisition Is Initialization) idiom is commonly used to manage resources in the context of exception handling. The basic idea behind RAII is to tie the lifetime of a resource (such as a dynamically allocated object) to the lifetime of an object with automatic storage duration (such as a local variable).

Here's an example that demonstrates the use of RAII for resource management:
```cpp
#include <iostream>
#include <memory>

using namespace std;

class Resource {
public:
   Resource() {
      cout << "Resource acquired" << endl;
   }

   ~Resource() {
      cout << "Resource released" << endl;
   }

   void doSomething() {
      cout << "Resource being used" << endl;
   }
};

int main() {
   try {
      Resource r; // Create a Resource object

      r.doSomething(); // Use the Resource object
      throw runtime_error("Exception!"); // Throw an exception
   }
   catch (const logic_error& e) {
      cerr << "Logic error caught: " << e.what() << endl;
   }

   return 0;
}
```
In this example, we have a class called `Resource`, which represents a resource that needs to be acquired and released. The `Resource` class has a constructor that acquires the resource and a destructor that releases the resource.

In the `main` function, we create a `Resource` object called `r`. We then call the `doSomething` function to use the `Resource` object. Finally, we throw a `std::runtime_error` exception.

Since there is no catch block for the `runtime_error` exception, the program will begin stack unwinding. As part of the stack unwinding process, the destructor of the `Resource` object `r` will be called, which will release the resource.

By using the RAII idiom, we can ensure that resources are properly managed in the context of exception handling.